<?xml version="1.0" ?>
<!-- =================================================================================== -->
<!-- |    This document was autogenerated by xacro from urdf/golf_cart.urdf.xacro      | -->
<!-- |    EDITING THIS FILE BY HAND IS NOT RECOMMENDED                                 | -->
<!-- =================================================================================== -->
<robot name="golf_cart">
  <!-- ===================== MATERIALS ===================== -->
  <material name="red">
    <color rgba="1 0 0 1"/>
  </material>
  <material name="black">
    <color rgba="0 0 0 1"/>
  </material>
  <!-- ===================== BASE FOOTPRINT ===================== -->
  <link name="base_footprint"/>
  <joint name="base_joint" type="fixed">
    <parent link="base_footprint"/>
    <child link="base_link"/>
    <!-- base_link origin at chassis center -->
    <origin rpy="0 0 0" xyz="0 0 0.15"/>
  </joint>
  <!-- ===================== BASE LINK ===================== -->
  <link name="base_link">
    <visual>
      <geometry>
        <box size="2.3 1.2 0.3"/>
      </geometry>
      <material name="red"/>
    </visual>
    <collision>
      <geometry>
        <box size="2.3 1.2 0.3"/>
      </geometry>
    </collision>
    <inertial>
      <mass value="150"/>
      <origin xyz="0 0 0"/>
      <inertia ixx="20" ixy="0" ixz="0" iyy="40" iyz="0" izz="50"/>
    </inertial>
  </link>
  <link name="rear_left_wheel">
    <visual>
      <geometry>
        <cylinder length="0.19304" radius="0.23"/>
      </geometry>
      <material name="black"/>
    </visual>
    <collision>
      <geometry>
        <cylinder length="0.19304" radius="0.23"/>
      </geometry>
    </collision>
    <inertial>
      <mass value="10"/>
      <origin xyz="0 0 0"/>
      <inertia ixx="0.1" ixy="0" ixz="0" iyy="0.1" iyz="0" izz="0.1"/>
    </inertial>
  </link>
  <link name="rear_right_wheel">
    <visual>
      <geometry>
        <cylinder length="0.19304" radius="0.23"/>
      </geometry>
      <material name="black"/>
    </visual>
    <collision>
      <geometry>
        <cylinder length="0.19304" radius="0.23"/>
      </geometry>
    </collision>
    <inertial>
      <mass value="10"/>
      <origin xyz="0 0 0"/>
      <inertia ixx="0.1" ixy="0" ixz="0" iyy="0.1" iyz="0" izz="0.1"/>
    </inertial>
  </link>
  <link name="front_left_wheel">
    <visual>
      <geometry>
        <cylinder length="0.19304" radius="0.23"/>
      </geometry>
      <material name="black"/>
    </visual>
    <collision>
      <geometry>
        <cylinder length="0.19304" radius="0.23"/>
      </geometry>
    </collision>
    <inertial>
      <mass value="10"/>
      <origin xyz="0 0 0"/>
      <inertia ixx="0.1" ixy="0" ixz="0" iyy="0.1" iyz="0" izz="0.1"/>
    </inertial>
  </link>
  <link name="front_right_wheel">
    <visual>
      <geometry>
        <cylinder length="0.19304" radius="0.23"/>
      </geometry>
      <material name="black"/>
    </visual>
    <collision>
      <geometry>
        <cylinder length="0.19304" radius="0.23"/>
      </geometry>
    </collision>
    <inertial>
      <mass value="10"/>
      <origin xyz="0 0 0"/>
      <inertia ixx="0.1" ixy="0" ixz="0" iyy="0.1" iyz="0" izz="0.1"/>
    </inertial>
  </link>
  <!-- ===================== WHEEL JOINT POSITIONS ===================== -->
  <!-- wheel z = -(base_height/2 + wheel_radius) = -(0.15 + 0.23) = -0.38 -->
  <!-- REAR LEFT -->
  <joint name="rear_left_wheel_joint" type="continuous">
    <parent link="base_link"/>
    <child link="rear_left_wheel"/>
    <origin rpy="1.5708 0 0" xyz="-1.15  0.5025 -0.38"/>
    <axis xyz="0 0 1"/>
  </joint>
  <!-- REAR RIGHT -->
  <joint name="rear_right_wheel_joint" type="continuous">
    <parent link="base_link"/>
    <child link="rear_right_wheel"/>
    <origin rpy="1.5708 0 0" xyz="-1.15 -0.5025 -0.38"/>
    <axis xyz="0 0 1"/>
  </joint>
  <!-- FRONT LEFT -->
  <joint name="front_left_wheel_joint" type="continuous">
    <parent link="base_link"/>
    <child link="front_left_wheel"/>
    <origin rpy="1.5708 0 0" xyz=" 1.15  0.5025 -0.38"/>
    <axis xyz="0 0 1"/>
  </joint>
  <!-- FRONT RIGHT -->
  <joint name="front_right_wheel_joint" type="continuous">
    <parent link="base_link"/>
    <child link="front_right_wheel"/>
    <origin rpy="1.5708 0 0" xyz=" 1.15 -0.5025 -0.38"/>
    <axis xyz="0 0 1"/>
  </joint>
</robot>
