<?xml version="1.0" ?>
<!-- =================================================================================== -->
<!-- |    This document was autogenerated by xacro from golf_cart3.urdf.xacro          | -->
<!-- |    EDITING THIS FILE BY HAND IS NOT RECOMMENDED                                 | -->
<!-- =================================================================================== -->
<robot name="golf_cart">
  <!-- ================================================= -->
  <!-- Dummy root link (KDL safe) -->
  <!-- ================================================= -->
  <link name="base_footprint"/>
  <!-- ================================================= -->
  <!-- Base link (rear axle center) -->
  <!-- ================================================= -->
  <link name="base_link">
    <visual>
      <geometry>
        <box size="2.5 1.2 0.4"/>
      </geometry>
      <origin xyz="1.15 0 0.4"/>
    </visual>
    <collision>
      <geometry>
        <box size="2.5 1.2 0.4"/>
      </geometry>
      <origin xyz="1.15 0 0.4"/>
    </collision>
    <inertial>
      <mass value="250"/>
      <origin xyz="1.15 0 0.4"/>
      <inertia ixx="40" ixy="0" ixz="0" iyy="60" iyz="0" izz="80"/>
    </inertial>
  </link>
  <joint name="base_footprint_to_base_link" type="fixed">
    <parent link="base_footprint"/>
    <child link="base_link"/>
    <origin xyz="0 0 0"/>
  </joint>
  <link name="rear_left_wheel_link">
    <visual>
      <geometry>
        <cylinder length="0.19304" radius="0.2355"/>
      </geometry>
      <origin rpy="1.5708 0 0"/>
    </visual>
    <collision>
      <geometry>
        <cylinder length="0.19304" radius="0.2355"/>
      </geometry>
      <origin rpy="1.5708 0 0"/>
    </collision>
    <inertial>
      <mass value="15"/>
      <inertia ixx="0.3" ixy="0" ixz="0" iyy="0.3" iyz="0" izz="0.3"/>
    </inertial>
  </link>
  <joint name="rear_left_wheel_joint" type="continuous">
    <parent link="base_link"/>
    <child link="rear_left_wheel_link"/>
    <origin xyz="0 0.5025 0.2355"/>
    <axis xyz="0 1 0"/>
  </joint>
  <link name="rear_right_wheel_link">
    <visual>
      <geometry>
        <cylinder length="0.19304" radius="0.2355"/>
      </geometry>
      <origin rpy="1.5708 0 0"/>
    </visual>
    <collision>
      <geometry>
        <cylinder length="0.19304" radius="0.2355"/>
      </geometry>
      <origin rpy="1.5708 0 0"/>
    </collision>
    <inertial>
      <mass value="15"/>
      <inertia ixx="0.3" ixy="0" ixz="0" iyy="0.3" iyz="0" izz="0.3"/>
    </inertial>
  </link>
  <joint name="rear_right_wheel_joint" type="continuous">
    <parent link="base_link"/>
    <child link="rear_right_wheel_link"/>
    <origin xyz="0 -0.5025 0.2355"/>
    <axis xyz="0 1 0"/>
  </joint>
  <!-- ================================================= -->
  <!-- Front steering links -->
  <!-- ================================================= -->
  <link name="front_left_steer_link">
    <inertial>
      <mass value="5.0"/>
      <origin xyz="0 0 0"/>
      <inertia ixx="0.01" ixy="0" ixz="0" iyy="0.01" iyz="0" izz="0.01"/>
    </inertial>
  </link>
  <joint name="front_left_steer_joint" type="revolute">
    <parent link="base_link"/>
    <child link="front_left_steer_link"/>
    <origin xyz="2.3 0.5025 0"/>
    <axis xyz="0 0 1"/>
    <limit effort="80" lower="-0.6" upper="0.6" velocity="1.5"/>
  </joint>
  <link name="front_right_steer_link">
    <inertial>
      <mass value="5.0"/>
      <origin xyz="0 0 0"/>
      <inertia ixx="0.01" ixy="0" ixz="0" iyy="0.01" iyz="0" izz="0.01"/>
    </inertial>
  </link>
  <joint name="front_right_steer_joint" type="revolute">
    <parent link="base_link"/>
    <child link="front_right_steer_link"/>
    <origin xyz="2.3 -0.5025 0"/>
    <axis xyz="0 0 1"/>
    <limit effort="80" lower="-0.6" upper="0.6" velocity="1.5"/>
  </joint>
  <link name="front_left_wheel_link">
    <visual>
      <geometry>
        <cylinder length="0.19304" radius="0.2355"/>
      </geometry>
      <origin rpy="1.5708 0 0"/>
    </visual>
    <collision>
      <geometry>
        <cylinder length="0.19304" radius="0.2355"/>
      </geometry>
      <origin rpy="1.5708 0 0"/>
    </collision>
    <inertial>
      <mass value="15"/>
      <inertia ixx="0.3" ixy="0" ixz="0" iyy="0.3" iyz="0" izz="0.3"/>
    </inertial>
  </link>
  <joint name="front_left_wheel_joint" type="continuous">
    <parent link="front_left_steer_link"/>
    <child link="front_left_wheel_link"/>
    <origin xyz="0 0 0.2355"/>
    <axis xyz="0 1 0"/>
  </joint>
  <link name="front_right_wheel_link">
    <visual>
      <geometry>
        <cylinder length="0.19304" radius="0.2355"/>
      </geometry>
      <origin rpy="1.5708 0 0"/>
    </visual>
    <collision>
      <geometry>
        <cylinder length="0.19304" radius="0.2355"/>
      </geometry>
      <origin rpy="1.5708 0 0"/>
    </collision>
    <inertial>
      <mass value="15"/>
      <inertia ixx="0.3" ixy="0" ixz="0" iyy="0.3" iyz="0" izz="0.3"/>
    </inertial>
  </link>
  <joint name="front_right_wheel_joint" type="continuous">
    <parent link="front_right_steer_link"/>
    <child link="front_right_wheel_link"/>
    <origin xyz="0 0 0.2355"/>
    <axis xyz="0 1 0"/>
  </joint>
  <!-- ================================================= -->
  <!-- ROS2 CONTROL (Ackermann) -->
  <!-- ================================================= -->
  <ros2_control name="AckermannSystem" type="system">
    <hardware>
      <plugin>gz_ros2_control/GazeboSystem</plugin>
    </hardware>
    <!-- Rear driven wheels -->
    <joint name="rear_left_wheel_joint">
      <command_interface name="velocity"/>
      <state_interface name="velocity"/>
    </joint>
    <joint name="rear_right_wheel_joint">
      <command_interface name="velocity"/>
      <state_interface name="velocity"/>
    </joint>
    <!-- Front steering joints -->
    <joint name="front_left_steer_joint">
      <command_interface name="position"/>
      <state_interface name="position"/>
    </joint>
    <joint name="front_right_steer_joint">
      <command_interface name="position"/>
      <state_interface name="position"/>
    </joint>
  </ros2_control>
  <!-- ================================================= -->
  <!-- Gazebo ros2_control plugin -->
  <!-- ================================================= -->
  <gazebo>
    <plugin filename="libgazebo_ros2_control.so" name="gazebo_ros2_control">
      <robot_param>robot_description</robot_param>
      <robot_param_node>robot_state_publisher</robot_param_node>
      <parameters> ~/ros2_ws/src/golf_cart_description/config/ackermann_controller.yaml</parameters>
    </plugin>
  </gazebo>
</robot>
